<?xml version="1.0"?>
<robot name="paletrone" xmlns:xacro="http://ros.org/wiki/xacro">

  <link name="world"/>

  <!-- Define X-axis prismatic joint and link -->
  <joint name="base_joint_X" type="prismatic">
    <parent link="world"/>
    <child link="base_link_X" />
    <origin xyz="0 0 0" rpy="0 0 0"/>
    <axis xyz="1 0 0"/>
    <limit lower="-0.5" upper="0.5" effort="100" velocity="0.1"/>
  </joint>
  <link name="base_link_X"/>

  <!-- Define Y-axis prismatic joint and link -->
  <joint name="base_joint_Y" type="prismatic">
    <parent link="base_link_X"/>
    <child link="base_link_Y" />
    <origin xyz="0 0 0" rpy="0 0 0"/>
    <axis xyz="0 1 0"/>
    <limit lower="-0.5" upper="0.5" effort="100" velocity="0.1"/>
  </joint>
  <link name="base_link_Y"/>

  <!-- Define Z-axis prismatic joint and link -->
  <joint name="base_joint_Z" type="prismatic">
    <parent link="base_link_Y"/>
    <child link="base_link_Z" />
    <origin xyz="0 0 0" rpy="0 0 0"/>
    <axis xyz="0 0 1"/>
    <limit lower="-0.5" upper="0.5" effort="100" velocity="0.1"/>
  </joint>
  <link name="base_link_Z"/>


  <!-- Define Z-axis revolute joint and link -->
  <joint name="base_joint_y" type="revolute">
    <parent link="base_link_Z"/>
    <child link="base_link_y" />
    <origin xyz="0 0 0" rpy="0 0 0"/>
    <axis xyz="0 0 1"/>
    <limit lower="-5" upper="5" effort="100" velocity="0.1"/>
  </joint>
  <link name="base_link_y"/>

  <!-- Define Y-axis revolute joint and link -->
  <joint name="base_joint_p" type="revolute">
    <parent link="base_link_y"/>
    <child link="base_link_p" />
    <origin xyz="0 0 0" rpy="0 0 0"/>
    <axis xyz="0 1 0"/>
    <limit lower="-5" upper="5" effort="100" velocity="0.1"/>
  </joint>
  <link name="base_link_p"/>

  <!-- Define X-axis revolute joint and link -->
  <joint name="base_joint_r" type="revolute">
    <parent link="base_link_p"/>
    <child link="base_link" />
    <origin xyz="0 0 0" rpy="0 0 0"/>
    <axis xyz="1 0 0"/>
    <limit lower="-5" upper="5" effort="100" velocity="0.1"/>
  </joint>

  <link name="base_link">
    <visual>
      <origin xyz="0 0 0.0" rpy="0 0 0"/>
      <geometry>
        <cylinder radius="0.05" length="0.1" />
      </geometry>
      <material name="light_black"/>
    </visual>

    <collision>
      <origin xyz="-0.064 0 0.047" rpy="0 0 0"/>
      <geometry>
        <box size="0.266 0.266 0.094"/>
      </geometry>
    </collision>

    <inertial>
      <origin xyz="0.0 0 0.0" rpy="0 0 0"/>
      <mass value="1.6329594e+00"/>
      <inertia ixx="1.0" ixy="0.0" ixz="0.0"
               iyy="1.0" iyz="0.0"
               izz="1.0" />
    </inertial>
  </link>

</robot>
